Workbook

Sheet SIGNAL 
B1: AUTOMATED PAIR TRADING SIGNAL - BUY ONLY WHEN ONE SIGNALS "BUY" AND OTHER SIGNALS "SELL" SIMULTANEOUSLY | AE1: @
B2: =IFERROR(__xludf.DUMMYFUNCTION("GOOGLEFINANCE(B5,""TRADETIME"")"),46311.64583333333) -> 46311.646 | C2: SIGNAL | E2: CORELATION % | J2: MAX RATIO | K2: MIN RATIO | M2: z score | O2: RATIO SPREAD | P2: PRICE | Q2: STANDARD DEVIATION | U2: DIVERGENCE
A3: LOT SIZE | B3: PAIR | C3: SELL | D3: BUY | E3: 30D | F3: 60 D | G3: 90D | H3: CORELEATION | I3: AVERAGE RATIO | J3: 60 Days | K3: 30 Days | L3: CURRENT | M3: MAX | N3: MIN | O3: CURRENT | P3: CURRENT | Q3: SMA 20 | R3: 2 SD | S3: MEAN | T3: -2SD | U3: CURRENT | W3: MAX | X3: MIN | Y3: CASH NEUTALITY RATIO | Z3: Price Diffrence | AA3: STOCK Number to BUY | AB3: Stock 1 Price | AC3: Stock 2 Value | AD3: BUY / sELL
A5: 700 | B5: NSE:ICICIBANK | C5: =if(AND(O5>J5,P5>=R5),"SELL Today","Do Not SELL Today") -> Do Not SELL Today | D5: =if(AND(P5<S5,O5<=K5,P5<=0.995*T5),"BUY Today","Do Not BUY Today") -> Do Not BUY Today | E5: ='ICICIBANK-HDFCBANK'!M2 -> -0.31463454 | F5: ='ICICIBANK-HDFCBANK'!M3 -> 0.25893018 | G5: ='ICICIBANK-HDFCBANK'!M4 -> 0.021267034 | H5: 30 DAYS | I5: ='ICICIBANK-HDFCBANK'!O2 -> 1.9230783 | J5: ='ICICIBANK-HDFCBANK'!P2 -> 2.0507757 | K5: ='ICICIBANK-HDFCBANK'!Q2 -> 1.7880172 | L5: ='ICICIBANK-HDFCBANK'!J128 -> 0.7366854 | M5: =maX('ICICIBANK-HDFCBANK'!J11:J117) -> 1.6632338 | N5: =MIN('ICICIBANK-HDFCBANK'!J11:J117) -> -1.5745616 | O5: =P5/P6 -> 1.9167181 | P5: =IFERROR(__xludf.DUMMYFUNCTION("GOOGLEFINANCE(B5,""PRICE"")"),1397.0) -> 1397 | Q5: =IFERROR(__xludf.DUMMYFUNCTION("AVERAGE(QUERY(SORT(GOOGLEFINANCE(B5,""price"",TODAY()-320,TODAY()),1,0),""select Col2 limit 20""))"),1340.6399999999999) -> 1340.64 | R5: ='ICICIBANK-HDFCBANK'!C3 -> 1427.5 | S5: ='ICICIBANK-HDFCBANK'!C8 -> 1351.7095 | T5: ='ICICIBANK-HDFCBANK'!C4 -> 1292.2 | U5: ='ICICIBANK-HDFCBANK'!O116 -> -0.040232758 | V5: 30 DAYS | W5: =MAX('ICICIBANK-HDFCBANK'!O87:O116) -> 0.04304118 | X5: =MIN('ICICIBANK-HDFCBANK'!O87:O116) -> -0.076354007 | Y5: =(P5*A5)/(P6*A6) -> 2.4394594 | Z5: =(A5*P5)-(A6*P6) -> 577032.5 | AA5: =if((AD5="BUY"), -(Z5/P5)) -> FALSE | AB5: =P5*A5 -> 977900 | AD5: =if( Z5<0,"Buy","Do Not buy") -> Do Not buy
A6: 550 | B6: NSE:HDFCBANK | C6: =if(AND(O6>J6,P6>=R6),"SELL Today","Do Not SELL Today") -> Do Not SELL Today | D6: =if(AND(P6<S6,O6<=K6,P6<=0.995*T6),"BUY Today","Do Not BUY Today") -> Do Not BUY Today | H6: 60 DAYS | I6: ='ICICIBANK-HDFCBANK'!O3 -> 1.9110265 | J6: ='ICICIBANK-HDFCBANK'!P3 -> 2.0507757 | K6: ='ICICIBANK-HDFCBANK'!Q3 -> 1.6985272 | O6: =P5/P6 -> 1.9167181 | P6: =IFERROR(__xludf.DUMMYFUNCTION("GOOGLEFINANCE(B6,""PRICE"")"),728.85) -> 728.85 | Q6: =IFERROR(__xludf.DUMMYFUNCTION("AVERAGE(QUERY(SORT(GOOGLEFINANCE(B6,""price"",TODAY()-320,TODAY()),1,0),""select Col2 limit 20""))"),719.315) -> 719.315 | R6: ='ICICIBANK-HDFCBANK'!F3 -> 739.5 | S6: ='ICICIBANK-HDFCBANK'!F8 -> 717.35952 | T6: ='ICICIBANK-HDFCBANK'!F4 -> 687.1 | V6: 60 days | W6: =MAX('ICICIBANK-HDFCBANK'!O57:O116) -> 0.096110898 | X6: =MIN('ICICIBANK-HDFCBANK'!O57:O116) -> -0.076354007 | AA6: =if((AD6="BUY"), (Z5/P6)) -> FALSE | AC6: =P6*A6 -> 400867.5
A8: 625 | B8: NSE:AXISBANK | C8: =if(AND(O8>J8,P8>=R8),"SELL Today","Do Not SELL Today") -> Do Not SELL Today | D8: =if(AND(P8<S8,O8<=K8,P8<=0.995*T8),"BUY Today","Do Not BUY Today") -> Do Not BUY Today | E8: ='AXISBANK-ICICIBANK'!N2 -> 0.74448663 | F8: ='AXISBANK-ICICIBANK'!N3 -> 0.37905168 | G8: ='AXISBANK-ICICIBANK'!N4 -> -0.09975295 | H8: 30 DAYS | I8: ='AXISBANK-ICICIBANK'!P2 -> 0.90180618 | J8: ='AXISBANK-ICICIBANK'!Q2 -> 0.93883038 | K8: ='AXISBANK-ICICIBANK'!R2 -> 0.86806776 | L8: ='AXISBANK-ICICIBANK'!J128 -> -0.23219858 | M8: =MAX('AXISBANK-ICICIBANK'!J11:J117) -> 1.4734222 | N8: =MIN('AXISBANK-ICICIBANK'!J11:J117) -> -1.516322 | O8: =P8/P9 -> 0.9234073 | P8: =IFERROR(__xludf.DUMMYFUNCTION("GOOGLEFINANCE(B8,""PRICE"")"),1290.0) -> 1290 | Q8: =IFERROR(__xludf.DUMMYFUNCTION("AVERAGE(QUERY(SORT(GOOGLEFINANCE(B8,""price"",TODAY()-320,TODAY()),1,0),""select Col2 limit 20""))"),1242.3850000000002) -> 1242.385 | R8: ='AXISBANK-ICICIBANK'!C3 -> 1273 | S8: ='AXISBANK-ICICIBANK'!C8 -> 1235.9714 | T8: ='AXISBANK-ICICIBANK'!C4 -> 1186.5 | U8: ='AXISBANK-ICICIBANK'!P116 -> 0.018594065 | V8: 30 DAYS | W8: =MAX('AXISBANK-ICICIBANK'!P87:P116) -> 0.05309431 | X8: =MIN('AXISBANK-ICICIBANK'!P87:P116) -> -0.01287434 | Y8: =(P8*A8)/(P9*A9) -> 0.8244708 | Z8: =(A8*P8)-(A9*P9) -> -171650 | AA8: =if((AD8="BUY"), -(Z8/P8)) -> 133.06202 | AB8: =P8*A8 -> 806250 | AD8: =if( Z8<0,"Buy","Do Not buy") -> Buy
A9: 700 | B9: NSE:ICICIBANK | C9: =if(AND(O9>J9,P9>=R9),"SELL Today","Do Not SELL Today") -> Do Not SELL Today | D9: =if(AND(P9<S9,O9<=K9,P9<=0.995*T9),"BUY Today","Do Not BUY Today") -> Do Not BUY Today | H9: 60 DAYS | I9: ='AXISBANK-ICICIBANK'!P3 -> 0.88935861 | J9: ='ICICIBANK-HDFCBANK'!P3 -> 2.0507757 | K9: ='AXISBANK-ICICIBANK'!R3 -> 0.84906965 | O9: =P8/P9 -> 0.9234073 | P9: =IFERROR(__xludf.DUMMYFUNCTION("GOOGLEFINANCE(B9,""PRICE"")"),1397.0) -> 1397 | Q9: =IFERROR(__xludf.DUMMYFUNCTION("AVERAGE(QUERY(SORT(GOOGLEFINANCE(B9,""price"",TODAY()-320,TODAY()),1,0),""select Col2 limit 20""))"),1340.6399999999999) -> 1340.64 | R9: ='AXISBANK-ICICIBANK'!F3 -> 1427.5 | S9: ='AXISBANK-ICICIBANK'!F8 -> 1351.7095 | T9: ='AXISBANK-ICICIBANK'!F4 -> 1292.2 | V9: 60 days | W9: =MAX('AXISBANK-ICICIBANK'!P57:P116) -> 0.05309431 | X9: =MIN('AXISBANK-ICICIBANK'!P57:P116) -> -0.10578715 | AA9: =if((AD9="BUY"), (Z8/P9)) -> FALSE | AC9: =P9*A9 -> 977900
A11: 650 | B11: NSE:CIPLA | C11: =if(AND(O11>J11,P11>=R11),"SELL Today","Do Not SELL Today") -> Do Not SELL Today | D11: =if(AND(P11<S11,O11>J11,P11<=0.995*T11),"BUY Today","Do Not BUY Today") -> Do Not BUY Today | E11: ='CIPLA-SUNPHARMA'!N2 -> 0.81677819 | F11: ='CIPLA-SUNPHARMA'!N3 -> 0.83419261 | G11: ='CIPLA-SUNPHARMA'!N4 -> 0.71443558 | H11: 30 DAYS | I11: ='CIPLA-SUNPHARMA'!P2 -> 0.7404995 | J11: =Max('CIPLA-SUNPHARMA'!Q2) -> 0.75899418 | K11: =Max('CIPLA-SUNPHARMA'!R2) -> 0.70999597 | L11: ='CIPLA-SUNPHARMA'!J128 -> 0.92294387 | M11: =MAX('CIPLA-SUNPHARMA'!J11:J117) -> 2.1777409 | N11: =MIN('CIPLA-SUNPHARMA'!J11:J117) -> -2.4493231 | O11: =P11/P12 -> 0.75341142 | P11: =IFERROR(__xludf.DUMMYFUNCTION("GOOGLEFINANCE(B11,""PRICE"")"),1325.1) -> 1325.1 | Q11: =IFERROR(__xludf.DUMMYFUNCTION("AVERAGE(QUERY(SORT(GOOGLEFINANCE(B11,""price"",TODAY()-320,TODAY()),1,0),""select Col2 limit 20""))"),1350.935) -> 1350.935 | R11: ='CIPLA-SUNPHARMA'!C3 -> 1399.7 | S11: ='CIPLA-SUNPHARMA'!C8 -> 1372.7048 | T11: ='CIPLA-SUNPHARMA'!C4 -> 1335.5 | U11: ='CIPLA-SUNPHARMA'!P116 -> 0.0068214377 | V11: 30 DAYS | W11: =MAX('CIPLA-SUNPHARMA'!P87:P116) -> 0.029296804 | X11: =MIN('CIPLA-SUNPHARMA'!P57:P116) -> -0.052989292 | Y11: =(P11*A11)/(P12*A12) -> 1.3991926 | Z11: =(A11*P11)-(A12*P12) -> 245735 | AA11: =if((AD11="BUY"), -(Z11/P11)) -> FALSE | AB11: =P11*A11 -> 861315 | AD11: =if( Z11<0,"Buy","Do Not buy") -> Do Not buy
A12: 350 | B12: NSE:SUNPHARMA | C12: =if(AND(O12>J12,P12>=R12),"SELL Today","Do Not SELL Today") -> Do Not SELL Today | D12: =if(AND(P12<S12,O12>J12,P12<=0.995*T12),"BUY Today","Do Not BUY Today") -> Do Not BUY Today | H12: 60 DAYS | I12: ='CIPLA-SUNPHARMA'!P3 -> 0.74151106 | J12: =Max('CIPLA-SUNPHARMA'!Q3) -> 0.76321263 | K12: =Max('CIPLA-SUNPHARMA'!R3) -> 0.70999597 | O12: =P11/P12 -> 0.75341142 | P12: =IFERROR(__xludf.DUMMYFUNCTION("GOOGLEFINANCE(B12,""PRICE"")"),1758.8) -> 1758.8 | Q12: =IFERROR(__xludf.DUMMYFUNCTION("AVERAGE(QUERY(SORT(GOOGLEFINANCE(B12,""price"",TODAY()-320,TODAY()),1,0),""select Col2 limit 20""))"),1806.2400000000002) -> 1806.24 | R12: ='CIPLA-SUNPHARMA'!F3 -> 1899 | S12: ='CIPLA-SUNPHARMA'!F8 -> 1848.8429 | T12: ='CIPLA-SUNPHARMA'!F4 -> 1779.7 | V12: 60 days | W12: =MAX('CIPLA-SUNPHARMA'!P57:P116) -> 0.029296804 | X12: =MIN('CIPLA-SUNPHARMA'!P57:P116) -> -0.052989292 | AA12: =if((AD12="BUY"), (Z11/P12)) -> FALSE | AC12: =P12*A12 -> 615580
A14: 1975 | B14: NSE:BPCL | C14: =if(AND(O14>J14,P14>=R14),"SELL Today","Do Not SELL Today") -> Do Not SELL Today | D14: =if(AND(P14<S14,O14>J14,P14<=0.995*T14),"BUY Today","Do Not BUY Today") -> Do Not BUY Today | E14: ='BPCL-HINDPETRO'!N2 -> 0.83864007 | F14: ='BPCL-HINDPETRO'!N3 -> 0.63805473 | G14: ='BPCL-HINDPETRO'!N4 -> 0.26896988 | H14: 30 DAYS | I14: ='BPCL-HINDPETRO'!P2 -> 0.86997676 | J14: =Max('BPCL-HINDPETRO'!Q2) -> 0.8902507 | K14: =Max('BPCL-HINDPETRO'!R2) -> 0.83855357 | L14: ='BPCL-HINDPETRO'!J128 -> 1.0531361 | M14: =MAX('BPCL-HINDPETRO'!J11:J117) -> 1.7562373 | N14: =MIN('BPCL-HINDPETRO'!J11:J117) -> -1.4694408 | O14: =P14/P15 -> 0.8482659 | P14: =IFERROR(__xludf.DUMMYFUNCTION("GOOGLEFINANCE(B14,""PRICE"")"),293.5) -> 293.5 | Q14: =IFERROR(__xludf.DUMMYFUNCTION("AVERAGE(QUERY(SORT(GOOGLEFINANCE(B14,""price"",TODAY()-320,TODAY()),1,0),""select Col2 limit 20""))"),299.68500000000006) -> 299.685 | R14: ='BPCL-HINDPETRO'!C3 -> 315.75 | S14: ='BPCL-HINDPETRO'!C8 -> 306.05 | T14: ='BPCL-HINDPETRO'!C4 -> 296.95 | U14: ='BPCL-HINDPETRO'!P117 -> -0.0051517579 | V14: 30 DAYS | W14: =MAX('BPCL-HINDPETRO'!P87:P116) -> 0.055224519 | X14: =MIN('BPCL-HINDPETRO'!P87:P116) -> -0.019910658 | Y14: =(P14*A14)/(P15*A15) -> 0.82732106 | Z14: =(A14*P14)-(A15*P15) -> -120987.5 | AA14: =if((AD14="BUY"), -(Z14/P14)) -> 412.22317 | AB14: =P14*A14 -> 579662.5 | AC14: =P14*A14 -> 579662.5 | AD14: =if( Z14<0,"Buy","Do Not buy") -> Buy
A15: 2025 | B15: NSE:HINDPETRO | C15: =if(AND(O15>J15,P15>=R15),"SELL Today","Do Not SELL Today") -> Do Not SELL Today | D15: =if(AND(P15<S15,O15>J15,P15<=0.995*T15),"BUY Today","Do Not BUY Today") -> Do Not BUY Today | H15: 60 DAYS | I15: ='BPCL-HINDPETRO'!P3 -> 0.84076878 | J15: =Max('BPCL-HINDPETRO'!Q3) -> 0.8902507 | K15: =Max('BPCL-HINDPETRO'!R3) -> 0.78117176 | O15: =P14/P15 -> 0.8482659 | P15: =IFERROR(__xludf.DUMMYFUNCTION("GOOGLEFINANCE(B15,""PRICE"")"),346.0) -> 346 | Q15: =IFERROR(__xludf.DUMMYFUNCTION("AVERAGE(QUERY(SORT(GOOGLEFINANCE(B15,""price"",TODAY()-320,TODAY()),1,0),""select Col2 limit 20""))"),345.08) -> 345.08 | R15: ='BPCL-HINDPETRO'!F3 -> 360.7 | S15: ='BPCL-HINDPETRO'!F8 -> 351.37857 | T15: ='BPCL-HINDPETRO'!F4 -> 342.35 | V15: 60 days | W15: =MAX('BPCL-HINDPETRO'!P57:P116) -> 0.055224519 | X15: =MIN('BPCL-HINDPETRO'!P57:P116) -> -0.019910658 | AA15: =if((AD15="BUY"), (Z14/P15)) -> FALSE
A17: 300 | B17: NSE:ACC | C17: =if(AND(O17>J17,P17>=R17),"SELL Today","Do Not SELL Today") -> Do Not SELL Today | D17: =if(AND(P17<S17,O17>J17,P17<=0.995*T17),"BUY Today","Do Not BUY Today") -> Do Not BUY Today | E17: ='ACC-AMBUJA'!N2 -> 0.9843871 | G17: ='ACC-AMBUJA'!N3 -> 0.99313904 | H17: 30 DAYS | I17: ='ACC-AMBUJA'!P2 -> 3.1949036 | J17: =Max('ACC-AMBUJA'!Q2) -> 3.2880383 | K17: =Max('ACC-AMBUJA'!R2) -> 3.1407407 | L17: ='ACC-AMBUJA'!J128 -> -2.1997257 | M17: =MAX('ACC-AMBUJA'!J11:J117) -> 1.65478 | N17: =MIN('ACC-AMBUJA'!J11:J117) -> -2.5707325 | O17: =P17/P18 -> 3.3083333 | P17: =IFERROR(__xludf.DUMMYFUNCTION("GOOGLEFINANCE(B17,""PRICE"")"),1191.0) -> 1191 | Q17: =IFERROR(__xludf.DUMMYFUNCTION("AVERAGE(QUERY(SORT(GOOGLEFINANCE(B17,""price"",TODAY()-320,TODAY()),1,0),""select Col2 limit 20""))"),1189.675) -> 1189.675 | R17: ='ACC-AMBUJA'!C3 -> 1283.8 | S17: ='ACC-AMBUJA'!C8 -> 1233.3619 | T17: ='ACC-AMBUJA'!C4 -> 1177 | U17: ='ACC-AMBUJA'!P116 -> 0.019538014 | V17: 30 DAYS | W17: =MAX('ACC-AMBUJA'!P87:P116) -> 0.029647884 | X17: =MIN('ACC-AMBUJA'!P87:P116) -> -0.0073152807 | Y17: =(P17*A17)/(P18*A18) -> 1.1027778 | Z17: =(A17*P17)-(A18*P18) -> 33300 | AA17: =if((AD17="BUY"), -(Z17/P17)) -> FALSE | AB17: =P17*A17 -> 357300 | AD17: =if( Z17<0,"Buy","Do Not buy") -> Do Not buy
A18: 900 | B18: NSE:AMBUJACEM | C18: =if(AND(O18>J18,P18>=R18),"SELL Today","Do Not SELL Today") -> Do Not SELL Today | D18: =if(AND(P18<S18,O18>J18,P18<=0.995*T18),"BUY Today","Do Not BUY Today") -> Do Not BUY Today | H18: 60 DAYS | I18: ='ACC-AMBUJA'!P3 -> 3.17563 | J18: =Max('ACC-AMBUJA'!Q3) -> 3.2880383 | K18: =Max('ACC-AMBUJA'!R3) -> 3.1241363 | O18: =P17/P18 -> 3.3083333 | P18: =IFERROR(__xludf.DUMMYFUNCTION("GOOGLEFINANCE(B18,""PRICE"")"),360.0) -> 360 | Q18: =IFERROR(__xludf.DUMMYFUNCTION("AVERAGE(QUERY(SORT(GOOGLEFINANCE(B18,""price"",TODAY()-320,TODAY()),1,0),""select Col2 limit 20""))"),366.9150000000001) -> 366.915 | R18: ='ACC-AMBUJA'!F3 -> 405 | S18: ='ACC-AMBUJA'!F8 -> 383.97143 | T18: ='ACC-AMBUJA'!F4 -> 361.55 | V18: 60 days | W18: =MAX('ACC-AMBUJA'!P57:P116) -> 0.029647884 | X18: =MIN('ACC-AMBUJA'!P57:P116) -> -0.011287948 | AA18: =if((AD18="BUY"), (Z17/P18)) -> FALSE | AC18: =P18*A18 -> 324000
A20: 175 | B20: NSE:TCS | C20: =if(AND(O20>J20,P20>=R20),"SELL Today","Do Not SELL Today") -> Do Not SELL Today | D20: =if(AND(P20<S20,O20>J20,P20<=0.995*T20),"BUY Today","Do Not BUY Today") -> Do Not BUY Today | E20: ='TCS-HCLTECH'!N2 -> 0.76671083 | F20: ='TCS-HCLTECH'!N3 -> 0.80626554 | G20: ='TCS-HCLTECH'!N4 -> 0.79020119 | H20: 30 DAYS | I20: ='TCS-HCLTECH'!P2 -> 1.7353166 | J20: =Max('TCS-HCLTECH'!Q2) -> 1.828456 | K20: =Max('TCS-HCLTECH'!R2) -> 1.6531215 | L20: ='TCS-HCLTECH'!J128 -> 0.73628214 | M20: =MAX('TCS-HCLTECH'!J11:J117) -> 2.4236684 | N20: =MIN('TCS-HCLTECH'!J11:J117) -> -2.1363544 | O20: =P20/P21 -> 1.7862319 | P20: =IFERROR(__xludf.DUMMYFUNCTION("GOOGLEFINANCE(B20,""PRICE"")"),2465.0) -> 2465 | Q20: =IFERROR(__xludf.DUMMYFUNCTION("AVERAGE(QUERY(SORT(GOOGLEFINANCE(B20,""price"",TODAY()-320,TODAY()),1,0),""select Col2 limit 20""))"),2143.3450000000003) -> 2143.345 | R20: ='TCS-HCLTECH'!C3 -> 2270 | S20: ='TCS-HCLTECH'!C8 -> 2137.5667 | T20: ='TCS-HCLTECH'!C4 -> 2032.4 | U20: ='TCS-HCLTECH'!P117 -> 0.013656121 | V20: 30 DAYS | W20: =MAX('TCS-HCLTECH'!P87:JP116) -> 0.037188776 | X20: =MIN('TCS-HCLTECH'!P87:P116) -> -0.061880057 | Y20: =(P20*A20)/(P21*A21) -> 0.89311594 | Z20: =(A20*P20)-(A21*P21) -> -51625 | AA20: =if((AD20="BUY"), -(Z20/P20)) -> 20.943205 | AB20: =P20*A20 -> 431375 | AD20: =if( Z20<0,"Buy","Do Not buy") -> Buy
A21: 350 | B21: NSE:HCLTECH | C21: =if(AND(O21>J21,P21>=R21),"SELL Today","Do Not SELL Today") -> Do Not SELL Today | D21: =if(AND(P21<S21,O21>J21,P21<=0.995*T21),"BUY Today","Do Not BUY Today") -> Do Not BUY Today | H21: 60 DAYS | I21: ='TCS-HCLTECH'!P3 -> 1.7629818 | J21: =Max('TCS-HCLTECH'!Q3) -> 1.8861747 | K21: =Max('TCS-HCLTECH'!R3) -> 1.6531215 | O21: =P20/P21 -> 1.7862319 | P21: =IFERROR(__xludf.DUMMYFUNCTION("GOOGLEFINANCE(B21,""PRICE"")"),1380.0) -> 1380 | Q21: =IFERROR(__xludf.DUMMYFUNCTION("AVERAGE(QUERY(SORT(GOOGLEFINANCE(B21,""price"",TODAY()-320,TODAY()),1,0),""select Col2 limit 20""))"),1255.3799999999999) -> 1255.38 | R21: ='TCS-HCLTECH'!F3 -> 1282.8 | S21: ='TCS-HCLTECH'!F8 -> 1241.2238 | T21: ='TCS-HCLTECH'!F4 -> 1185 | V21: 60 days | W21: =MAX('TCS-HCLTECH'!P57:P116) -> 0.037188776 | X21: =MIN('TCS-HCLTECH'!P57:P116) -> -0.061880057 | AA21: =if((AD21="BUY"), (Z20/P21)) -> FALSE | AC21: =P21*A21 -> 483000
A23: 5500 | B23: NSE:TATASTEEL | C23: =if(AND(O23>J23,P23>=R23),"SELL Today","Do Not SELL Today") -> Do Not SELL Today | D23: =if(AND(P23<S23,O23>J23,P23<=0.995*T23),"BUY Today","Do Not BUY Today") -> Do Not BUY Today | E23: ='TATASTEEL-JSWSTEEL1'!N2 -> 0.61312346 | F23: ='TATASTEEL-JSWSTEEL1'!N3 -> 0.48024676 | G23: ='TATASTEEL-JSWSTEEL1'!N4 -> 0.27543409 | H23: 30 DAYS | I23: ='TATASTEEL-JSWSTEEL1'!P2 -> 0.14397069 | J23: =Max('TATASTEEL-JSWSTEEL1'!Q2) -> 0.14942556 | K23: =Max('TATASTEEL-JSWSTEEL1'!R2) -> 0.13966355 | L23: ='TATASTEEL-JSWSTEEL1'!J128 -> 1.3975332 | M23: =MAX('TATASTEEL-JSWSTEEL1'!J11:J117) -> 1.7364237 | N23: =MIN('TATASTEEL-JSWSTEEL1'!J11:J117) -> -2.4939845 | O23: =P23/P24 -> 0.14429006 | P23: =IFERROR(__xludf.DUMMYFUNCTION("GOOGLEFINANCE(B23,""PRICE"")"),175.5) -> 175.5 | Q23: =IFERROR(__xludf.DUMMYFUNCTION("AVERAGE(QUERY(SORT(GOOGLEFINANCE(B23,""price"",TODAY()-320,TODAY()),1,0),""select Col2 limit 20""))"),180.459) -> 180.459 | R23: ='TATASTEEL-JSWSTEEL1'!C3 -> 190.82 | S23: ='TATASTEEL-JSWSTEEL1'!C8 -> 184.3819 | T23: ='TATASTEEL-JSWSTEEL1'!C4 -> 175.64 | U23: ='TATASTEEL-JSWSTEEL1'!P117 -> -0.026567012 | V23: 30 DAYS | W23: =MAX('TATASTEEL-JSWSTEEL1'!P87:P116) -> 0.051196407 | X23: =MIN('TATASTEEL-JSWSTEEL1'!P87:P116) -> -0.03361178 | Y23: =(P23*A23)/(P24*A24) -> 1.1756968 | Z23: =(A23*P23)-(A24*P24) -> 144247.5 | AA23: =if((AD23="BUY"), -(Z23/P23)) -> FALSE | AB23: =P23*A23 -> 965250 | AD23: =if( Z23<0,"Buy","Do Not buy") -> Do Not buy
A24: 675 | B24: NSE:JSWSTEEL | C24: =if(AND(O24>J24,P24>=R24),"SELL Today","Do Not SELL Today") -> Do Not SELL Today | D24: =if(AND(P24<S24,O24>J24,P24<=0.995*T24),"BUY Today","Do Not BUY Today") -> Do Not BUY Today | H24: 60 DAYS | I24: ='TATASTEEL-JSWSTEEL1'!P3 -> 0.14542925 | J24: =Max('TATASTEEL-JSWSTEEL1'!Q3) -> 0.15191646 | K24: =Max('TATASTEEL-JSWSTEEL1'!R3) -> 0.13966355 | O24: =P23/P24 -> 0.14429006 | P24: =IFERROR(__xludf.DUMMYFUNCTION("GOOGLEFINANCE(B24,""PRICE"")"),1216.3) -> 1216.3 | Q24: =IFERROR(__xludf.DUMMYFUNCTION("AVERAGE(QUERY(SORT(GOOGLEFINANCE(B24,""price"",TODAY()-320,TODAY()),1,0),""select Col2 limit 20""))"),1234.6349999999998) -> 1234.635 | R24: ='TATASTEEL-JSWSTEEL1'!F3 -> 1310 | S24: ='TATASTEEL-JSWSTEEL1'!F8 -> 1267.4667 | T24: ='TATASTEEL-JSWSTEEL1'!F4 -> 1229.2 | V24: 60 days | W24: =MAX('TATASTEEL-JSWSTEEL1'!P57:P116) -> 0.051196407 | X24: =MIN('TATASTEEL-JSWSTEEL1'!P57:P116) -> -0.03361178 | AA24: =if((AD24="BUY"), (Z23/P24)) -> FALSE | AC24: =P24*A24 -> 821002.5
A26: 200 | B26: NSE:NESTLEIND | C26: =if(AND(O26>J26,P26>=R26),"SELL Today","Do Not SELL Today") -> Do Not SELL Today | D26: =if(AND(P26<S26,O26>J26,P26<=0.995*T26),"BUY Today","Do Not BUY Today") -> Do Not BUY Today | E26: ='NESTLE-HINDUNILVR'!N2 -> 0.9122198 | F26: ='NESTLE-HINDUNILVR'!N3 -> 0.76447922 | G26: ='NESTLE-HINDUNILVR'!N4 -> 0.43604026 | H26: 30 DAYS | I26: ='NESTLE-HINDUNILVR'!P2 -> 0.71550407 | J26: =Max('NESTLE-HINDUNILVR'!Q2) -> 0.76064857 | K26: =Max('NESTLE-HINDUNILVR'!R2) -> 0.69714225 | L26: ='NESTLE-HINDUNILVR'!J128 -> 0.3632604 | M26: =MAX('NESTLE-HINDUNILVR'!J11:J117) -> 1.8928575 | N26: =MIN('NESTLE-HINDUNILVR'!J11:J117) -> -1.8125768 | O26: =P26/P27 -> 0.66823318 | P26: =IFERROR(__xludf.DUMMYFUNCTION("GOOGLEFINANCE(B26,""PRICE"")"),1265.5) -> 1265.5 | Q26: =IFERROR(__xludf.DUMMYFUNCTION("AVERAGE(QUERY(SORT(GOOGLEFINANCE(B26,""price"",TODAY()-320,TODAY()),1,0),""select Col2 limit 20""))"),1336.4600000000003) -> 1336.46 | R26: ='NESTLE-HINDUNILVR'!C3 -> 1410.5 | S26: ='NESTLE-HINDUNILVR'!C8 -> 1364.6952 | T26: ='NESTLE-HINDUNILVR'!C4 -> 1297.1 | U26: ='NESTLE-HINDUNILVR'!P116 -> 0.0034325215 | V26: 30 DAYS | W26: =MAX('NESTLE-HINDUNILVR'!P87:P116) -> 0.045728687 | X26: =MAX('NESTLE-HINDUNILVR'!P87:P116) -> 0.045728687 | Y26: =(P26*A26)/(P27*A27) -> 0.44548879 | Z26: =(A26*P26)-(A27*P27) -> -315040 | AA26: =if((AD26="BUY"), -(Z26/P26)) -> 248.94508 | AB26: =P26*A26 -> 253100 | AD26: =if( Z26<0,"Buy","Do Not buy") -> Buy
A27: 300 | B27: NSE:HINDUNILVR | C27: =if(AND(O27>J27,P27>=R27),"SELL Today","Do Not SELL Today") -> Do Not SELL Today | D27: =if(AND(P27<S27,O27>J27,P27<=0.995*T27),"BUY Today","Do Not BUY Today") -> Do Not BUY Today | F27: ='NESTLE-HINDUNILVR'!K7 | H27: 60 DAYS | I27: ='NESTLE-HINDUNILVR'!P3 -> 0.7099397 | J27: =Max('NESTLE-HINDUNILVR'!Q3) -> 0.76064857 | K27: =Max('NESTLE-HINDUNILVR'!R3) -> 0.66499586 | O27: =P26/P27 -> 0.66823318 | P27: =IFERROR(__xludf.DUMMYFUNCTION("GOOGLEFINANCE(B27,""PRICE"")"),1893.8) -> 1893.8 | Q27: =IFERROR(__xludf.DUMMYFUNCTION("AVERAGE(QUERY(SORT(GOOGLEFINANCE(B27,""price"",TODAY()-320,TODAY()),1,0),""select Col2 limit 20""))"),1889.845) -> 1889.845 | R27: ='NESTLE-HINDUNILVR'!F3 -> 1980 | S27: ='NESTLE-HINDUNILVR'!F8 -> 1924.6524 | T27: ='NESTLE-HINDUNILVR'!F4 -> 1836 | V27: 60 days | W27: =MAX('NESTLE-HINDUNILVR'!P57:P116) -> 0.089442222 | X27: =MIN('NESTLE-HINDUNILVR'!P57:P116) -> -0.027094349 | AA27: =if((AD27="BUY"), (Z26/P27)) -> FALSE | AC27: =P27*A27 -> 568140
A29: 25 | B29: INDEXNSE:NIFTY_50 | C29: =if(AND(O29>J29,P29>=R29),"SELL Today","Do Not SELL Today") -> Do Not SELL Today | D29: =if(AND(P29<S29,O29>J29,P29<=0.995*T29),"BUY Today","Do Not BUY Today") -> Do Not BUY Today | E29: ='NIFTY-BANKNIFTY'!N2 -> 0.97145202 | F29: ='NIFTY-BANKNIFTY'!N3 -> 0.94216834 | G29: ='NIFTY-BANKNIFTY'!N4 -> 0.83448052 | H29: 30 DAYS | I29: ='NIFTY-BANKNIFTY'!P2 -> 0.41643472 | J29: =MAX('NIFTY-BANKNIFTY'!Q2) -> 0.42310508 | K29: =MAX('NIFTY-BANKNIFTY'!R2) -> 0.41178404 | L29: ='NIFTY-BANKNIFTY'!J128 -> -0.093498457 | M29: =MAX('NIFTY-BANKNIFTY'!J11:J117) -> 2.2777198 | N29: =MIN('NIFTY-BANKNIFTY'!J11:J117) -> -1.3057041 | O29: =P29/P30 -> 0.41447873 | P29: =IFERROR(__xludf.DUMMYFUNCTION("GOOGLEFINANCE(B29,""PRICE"")"),23146.15) -> 23146.15 | Q29: =IFERROR(__xludf.DUMMYFUNCTION("AVERAGE(QUERY(SORT(GOOGLEFINANCE(B29,""price"",TODAY()-320,TODAY()),1,0),""select Col2 limit 20""))"),22840.879999999997) -> 22840.88 | R29: ='NIFTY-BANKNIFTY'!C3 -> 23897.7 | S29: ='NIFTY-BANKNIFTY'!C8 -> 23182.712 | T29: ='NIFTY-BANKNIFTY'!C4 -> 22421.95 | U29: ='NIFTY-BANKNIFTY'!P116 -> -0.0088068348 | V29: 30 DAYS | W29: =MAX('NIFTY-BANKNIFTY'!P87:P117) -> 0.0068758062 | X29: =MIN('NIFTY-BANKNIFTY'!P87:Q117) -> -0.017513388 | Y29: =(P29*A29)/(P30*A30) -> 0.69079788 | Z29: =(A29*P29)-(A30*P30) -> -259006.25 | AA29: =if((AD29="BUY"), -(Z29/P29)) -> 11.190036 | AB29: =P29*A29 -> 578653.75 | AD29: =if( Z29<0,"Buy","Do Not buy") -> Buy
A30: 15 | B30: INDEXNSE:NIFTY_BANK | C30: =if(AND(O30>J30,P30>=R30),"SELL Today","Do Not SELL Today") -> Do Not SELL Today | D30: =if(AND(P30<S30,O30>J30,P30<=0.995*T30),"BUY Today","Do Not BUY Today") -> Do Not BUY Today | H30: 60 DAYS | I30: ='NIFTY-BANKNIFTY'!P3 -> 0.41910093 | J30: ='NIFTY-BANKNIFTY'!Q3 -> 0.42647508 | K30: ='NIFTY-BANKNIFTY'!R3 -> 0.41178404 | O30: =P29/P30 -> 0.41447873 | P30: =IFERROR(__xludf.DUMMYFUNCTION("GOOGLEFINANCE(B30,""PRICE"")"),55844.0) -> 55844 | Q30: =IFERROR(__xludf.DUMMYFUNCTION("AVERAGE(QUERY(SORT(GOOGLEFINANCE(B30,""price"",TODAY()-320,TODAY()),1,0),""select Col2 limit 20""))"),55323.37000000001) -> 55323.37 | R30: ='NIFTY-BANKNIFTY'!F3 -> 57369.65 | S30: ='NIFTY-BANKNIFTY'!F8 -> 55858.243 | T30: ='NIFTY-BANKNIFTY'!F4 -> 54259.95 | V30: 60 days | W30: =MAX('NIFTY-BANKNIFTY'!P57:P117) -> 0.014329066 | X30: =MIN('NIFTY-BANKNIFTY'!P57:P117) -> -0.017513388 | AA30: =if((AD30="BUY"), (Z29/P30)) -> FALSE | AC30: =P30*A30 -> 837660
A32: 200 | B32: NSE:BRITANNIA | C32: =if(AND(O32>J32,P32>=R32),"SELL Today","Do Not SELL Today") -> Do Not SELL Today | D32: =if(AND(P32<S32,O32>J32,P32<=0.995*T32),"BUY Today","Do Not BUY Today") -> Do Not BUY Today | E32: ='BRITANIA-UNILEVER'!N2 -> 0.92419844 | F32: ='BRITANIA-UNILEVER'!N3 -> 0.85353658 | G32: ='BRITANIA-UNILEVER'!N4 -> 0.59761087 | H32: 30 DAYS | I32: ='BRITANIA-UNILEVER'!P2 -> 2.5919073 | J32: =Max('BRITANIA-UNILEVER'!Q2) -> 2.6684965 | K32: =Max('BRITANIA-UNILEVER'!R2) -> 2.5276923 | L32: ='BRITANIA-UNILEVER'!J130 -> -1.8073249 | M32: =MAX('BRITANIA-UNILEVER'!J11:J117) -> 2.3150285 | N32: =min('BRITANIA-UNILEVER'!J11:J117) -> -1.4519795 | O32: =P32/P33 -> 2.5155771 | P32: =IFERROR(__xludf.DUMMYFUNCTION("GOOGLEFINANCE(B32,""PRICE"")"),4764.0) -> 4764 | Q32: =IFERROR(__xludf.DUMMYFUNCTION("AVERAGE(QUERY(SORT(GOOGLEFINANCE(B32,""price"",TODAY()-320,TODAY()),1,0),""select Col2 limit 20""))"),4859.035000000001) -> 4859.035 | R32: ='BRITANIA-UNILEVER'!C3 -> 5101.5 | S32: ='BRITANIA-UNILEVER'!C8 -> 4948.1095 | T32: ='BRITANIA-UNILEVER'!C4 -> 4770 | U32: ='BRITANIA-UNILEVER'!P116 -> 0.012410799 | V32: 30 DAYS | W32: =MAX('BRITANIA-UNILEVER'!P87:P116) -> 0.035357141 | X32: =MIN('BRITANIA-UNILEVER'!P87:P116) -> -0.036407541 | Y32: =(P32*A32)/(P33*A33) -> 1.6770514 | Z32: =(A32*P32)-(A33*P33) -> 384660 | AA32: =if((AD32="BUY"), -(Z32/P32)) -> FALSE | AB32: =P32*A32 -> 952800 | AD32: =if( Z32<0,"Buy","Do Not buy") -> Do Not buy
A33: 300 | B33: NSE:HINDUNILVR | C33: =if(AND(O33>J33,P33>=R33),"SELL Today","Do Not SELL Today") -> Do Not SELL Today | D33: =if(AND(P33<S33,O33>J33,P33<=0.995*T33),"BUY Today","Do Not BUY Today") -> Do Not BUY Today | H33: 60 DAYS | I33: ='BRITANIA-UNILEVER'!P3 -> 2.5973517 | J33: =Max('BRITANIA-UNILEVER'!Q3) -> 2.7365487 | K33: =Max('BRITANIA-UNILEVER'!R3) -> 2.4760876 | O33: =P32/P33 -> 2.5155771 | P33: =IFERROR(__xludf.DUMMYFUNCTION("GOOGLEFINANCE(B33,""PRICE"")"),1893.8) -> 1893.8 | Q33: =IFERROR(__xludf.DUMMYFUNCTION("AVERAGE(QUERY(SORT(GOOGLEFINANCE(B33,""price"",TODAY()-320,TODAY()),1,0),""select Col2 limit 20""))"),1889.845) -> 1889.845 | R33: ='BRITANIA-UNILEVER'!F3 -> 1980 | S33: ='BRITANIA-UNILEVER'!F8 -> 1924.6524 | T33: ='BRITANIA-UNILEVER'!F4 -> 1836 | V33: 60 days | W33: =MAX('BRITANIA-UNILEVER'!P57:P116) -> 0.07944715 | X33: =MIN('BRITANIA-UNILEVER'!P57:P116) -> -0.036407541 | AA33: =if((AD33="BUY"), (Z32/P33)) -> FALSE | AC33: =P33*A33 -> 568140
A35: 100 | B35: NSE:BAJFINANCE | C35: =if(AND(O35>J35,P35>=R35),"SELL Today","Do Not SELL Today") -> Do Not SELL Today | D35: =if(AND(P35<S35,O35>J35,P35<=0.995*T35),"BUY Today","Do Not BUY Today") -> Do Not BUY Today | E35: ='BAJFINANCE-BAJFINSV'!N2 -> 0.95651131 | F35: ='BAJFINANCE-BAJFINSV'!N3 -> 0.93591475 | G35: ='BAJFINANCE-BAJFINSV'!N4 -> 0.9320949 | H35: 30 DAYS | I35: ='BAJFINANCE-BAJFINSV'!P2 -> 0.5455664 | J35: =Max('BAJFINANCE-BAJFINSV'!Q2) -> 0.56496074 | K35: =Max('BAJFINANCE-BAJFINSV'!R2) -> 0.52300841 | L35: ='BAJFINANCE-BAJFINSV'!J128 -> 2.0222575 | M35: =MAX('BAJFINANCE-BAJFINSV'!J11:J117) -> 1.6413371 | N35: =MIN('BAJFINANCE-BAJFINSV'!J11:J117) -> -2.0920613 | O35: =P35/P36 -> 0.56801619 | P35: =IFERROR(__xludf.DUMMYFUNCTION("GOOGLEFINANCE(B35,""PRICE"")"),982.1) -> 982.1 | Q35: =IFERROR(__xludf.DUMMYFUNCTION("AVERAGE(QUERY(SORT(GOOGLEFINANCE(B35,""price"",TODAY()-320,TODAY()),1,0),""select Col2 limit 20""))"),980.8124999999998) -> 980.8125 | R35: ='BAJFINANCE-BAJFINSV'!C3 -> 1060 | S35: ='BAJFINANCE-BAJFINSV'!C8 -> 1005.6071 | T35: ='BAJFINANCE-BAJFINSV'!C4 -> 948.3 | U35: ='BAJFINANCE-BAJFINSV'!P116 -> 0.0065439307 | V35: 30 DAYS | W35: =MAX('BAJFINANCE-BAJFINSV'!P87:P116) -> 0.042152363 | X35: =MIN('BAJFINANCE-BAJFINSV'!P87:P116) -> -0.034494464 | Y35: =(P35*A35)/(P36*A36) -> 0.11360324 | Z35: =(A35*P35)-(A36*P36) -> -766290 | AA35: =if((AD35="BUY"), -(Z35/P35)) -> 780.25659 | AB35: =P35*A35 -> 98210 | AD35: =if( Z35<0,"Buy","Do Not buy") -> Buy
A36: 500 | B36: NSE:BAJAJFINSV | C36: =if(AND(O36>J36,P36>=R36),"SELL Today","Do Not SELL Today") -> Do Not SELL Today | D36: =if(AND(P36<S36,O36>J36,P36<=0.995*T36),"BUY Today","Do Not BUY Today") -> Do Not BUY Today | H36: 60 DAYS | I36: ='BAJFINANCE-BAJFINSV'!P3 -> 0.54697694 | J36: =Max('BAJFINANCE-BAJFINSV'!Q3) -> 0.57158206 | K36: =Max('BAJFINANCE-BAJFINSV'!R3) -> 0.52300841 | O36: =P35/P36 -> 0.56801619 | P36: =IFERROR(__xludf.DUMMYFUNCTION("GOOGLEFINANCE(B36,""PRICE"")"),1729.0) -> 1729 | Q36: =IFERROR(__xludf.DUMMYFUNCTION("AVERAGE(QUERY(SORT(GOOGLEFINANCE(B36,""price"",TODAY()-320,TODAY()),1,0),""select Col2 limit 20""))"),1760.58) -> 1760.58 | R36: ='BAJFINANCE-BAJFINSV'!F3 -> 1940.5 | S36: ='BAJFINANCE-BAJFINSV'!F8 -> 1824.7619 | T36: ='BAJFINANCE-BAJFINSV'!F4 -> 1731 | V36: 60 days | W36: =MAX('BAJFINANCE-BAJFINSV'!P57:P116) -> 0.042152363 | X36: =MIN('BAJFINANCE-BAJFINSV'!P57:P116) -> -0.034494464 | AA36: =if((AD36="BUY"), (Z35/P36)) -> FALSE | AC36: =P36*A36 -> 864500
A38: 550 | B38: NSE:HDFCBANK | C38: =if(AND(O38>J38,P38>=R38),"SELL Today","Do Not SELL Today") -> Do Not SELL Today | D38: =if(AND(P38<S38,O38>J38,P38<=0.995*T38),"BUY Today","Do Not BUY Today") -> Do Not BUY Today | E38: ='HDFC-BANKNIFTY'!N2 -> -0.03060102 | F38: ='HDFC-BANKNIFTY'!N3 -> 0.42514756 | G38: ='HDFC-BANKNIFTY'!N4 -> 0.37817542 | H38: 30 DAYS | I38: ='HDFC-BANKNIFTY'!P2 -> 0.012714639 | J38: =Max('HDFC-BANKNIFTY'!Q2) -> 0.013319216 | K38: =Max('HDFC-BANKNIFTY'!R4) -> 0.012205228 | L38: ='HDFC-BANKNIFTY'!J128 -> 0.37271316 | M38: =MAX('HDFC-BANKNIFTY'!J11:J117) -> 2.0146355 | N38: =MIN('HDFC-BANKNIFTY'!J11:J117) -> -1.3478314 | O38: =P38/P39 -> 0.013051536 | P38: =IFERROR(__xludf.DUMMYFUNCTION("GOOGLEFINANCE(B38,""PRICE"")"),728.85) -> 728.85 | Q38: =IFERROR(__xludf.DUMMYFUNCTION("AVERAGE(QUERY(SORT(GOOGLEFINANCE(B38,""price"",TODAY()-320,TODAY()),1,0),""select Col2 limit 20""))"),719.315) -> 719.315 | R38: ='HDFC-BANKNIFTY'!C3 -> 739.5 | S38: ='HDFC-BANKNIFTY'!C8 -> 717.35952 | T38: ='HDFC-BANKNIFTY'!C4 -> 687.1 | U38: ='HDFC-BANKNIFTY'!P116 -> 0.033754805 | V38: 30 DAYS | W38: =MAX('HDFC-BANKNIFTY'!P87:P116) -> 0.045694837 | X38: =MIN('HDFC-BANKNIFTY'!P87:P116) -> -0.031481316 | Y38: =(P38*A38)/(P39*A39) -> 0.47855634 | Z38: =(A38*P38)-(A39*P39) -> -436792.5 | AA38: =if((AD38="BUY"), -(Z38/P38)) -> 599.28998 | AB38: =P38*A38 -> 400867.5 | AD38: =if( Z38<0,"Buy","Do Not buy") -> Buy
A39: 15 | B39: INDEXNSE:NIFTY_BANK | C39: =if(AND(O39>J39,P39>=R39),"SELL Today","Do Not SELL Today") -> Do Not SELL Today | D39: =if(AND(P39<S39,O39>J39,P39<=0.995*T39),"BUY Today","Do Not BUY Today") -> Do Not BUY Today | H39: 60 DAYS | I39: ='HDFC-BANKNIFTY'!P3 -> 0.012912383 | J39: =Max('HDFC-BANKNIFTY'!Q3) -> 0.014212029 | K39: =Max('HDFC-BANKNIFTY'!R3) -> 0.012205228 | O39: =P38/P39 -> 0.013051536 | P39: =IFERROR(__xludf.DUMMYFUNCTION("GOOGLEFINANCE(B39,""PRICE"")"),55844.0) -> 55844 | Q39: =IFERROR(__xludf.DUMMYFUNCTION("AVERAGE(QUERY(SORT(GOOGLEFINANCE(B39,""price"",TODAY()-320,TODAY()),1,0),""select Col2 limit 20""))"),55323.37000000001) -> 55323.37 | R39: ='HDFC-BANKNIFTY'!F3 -> 57369.65 | S39: ='HDFC-BANKNIFTY'!F8 -> 55858.243 | T39: ='HDFC-BANKNIFTY'!F4 -> 54259.95 | V39: 60 days | W39: =MAX('HDFC-BANKNIFTY'!P57:P116) -> 0.045694837 | X39: =MIN('HDFC-BANKNIFTY'!P57:P116) -> -0.064977788 | AA39: =if((AD39="BUY"), (Z38/P39)) -> FALSE | AC39: =P39*A39 -> 837660
A41: 2000 | B41: NSE:RECLTD | C41: =if(AND(O41>J41,P41>=R41),"SELL Today","Do Not SELL Today") -> Do Not SELL Today | D41: =if(AND(P41<S41,O41>J41,P41<=0.995*T41),"BUY Today","Do Not BUY Today") -> Do Not BUY Today | E41: ='REC-PFC'!N2 -> 0.89960058 | F41: ='REC-PFC'!N3 -> 0.98531788 | G41: ='REC-PFC'!N4 -> 0.90025081 | H41: 30 DAYS | I41: ='REC-PFC'!P2 -> 0.90403837 | J41: ='REC-PFC'!Q2 -> 0.96134404 | K41: ='REC-PFC'!R2 -> 0.88402458 | L41: ='REC-PFC'!J129 -> 1.3569929 | M41: ='REC-PFC'!K129 -> 0.92363091 | N41: =mIN('REC-PFC'!J11:J117) -> -1.9014783 | O41: =P41/P42 -> 0.92363091 | P41: =IFERROR(__xludf.DUMMYFUNCTION("GOOGLEFINANCE(B41,""PRICE"")"),307.8) -> 307.8 | Q41: =IFERROR(__xludf.DUMMYFUNCTION("AVERAGE(QUERY(SORT(GOOGLEFINANCE(B41,""price"",TODAY()-320,TODAY()),1,0),""select Col2 limit 20""))"),303.5675) -> 303.5675 | R41: ='REC-PFC'!C3 -> 318.7 | S41: ='REC-PFC'!C8 -> 307.89048 | T41: ='REC-PFC'!C4 -> 287.75 | U41: ='REC-PFC'!P116 -> 0.0036222877 | V41: 30 DAYS | W41: =MAX('REC-PFC'!P87:P116) -> 0.074976321 | X41: =MIN('REC-PFC'!P87:P116) -> -0.01923081 | Y41: =(P41*A41)/(P42*A42) -> 1.4209706 | Z41: =(A41*P41)-(A42*P42) -> 182375 | AA41: =if((AD41="BUY"), -(Z41/P41)) -> FALSE | AB41: =P41*A41 -> 615600 | AD41: =if( Z41<0,"Buy","Do Not buy") -> Do Not buy
A42: 1300 | B42: NSE:PFC | C42: =if(AND(O42>J42,P42>=R42),"SELL Today","Do Not SELL Today") -> Do Not SELL Today | D42: =if(AND(P42<S42,O42>J42,P42<=0.995*T42),"BUY Today","Do Not BUY Today") -> Do Not BUY Today | H42: 60 DAYS | I42: ='REC-PFC'!P3 -> 0.89326163 | J42: ='REC-PFC'!Q3 -> 0.96134404 | K42: ='REC-PFC'!R3 -> 0.86142002 | O42: =P41/P42 -> 0.92363091 | P42: =IFERROR(__xludf.DUMMYFUNCTION("GOOGLEFINANCE(B42,""PRICE"")"),333.25) -> 333.25 | Q42: =IFERROR(__xludf.DUMMYFUNCTION("AVERAGE(QUERY(SORT(GOOGLEFINANCE(B42,""price"",TODAY()-320,TODAY()),1,0),""select Col2 limit 20""))"),333.785) -> 333.785 | R42: ='REC-PFC'!F3 -> 355.9 | S42: ='REC-PFC'!F8 -> 340.75476 | T42: ='REC-PFC'!F4 -> 318 | V42: 60 days | W42: =MAX('REC-PFC'!P57:P116) -> 0.074976321 | X42: =MIN('REC-PFC'!P57:P116) -> -0.01923081 | AA42: =if((AD42="BUY"), (Z41/P42)) -> FALSE | AC42: =P42*A42 -> 433225
A44: 1375 | B44: NSE:IGL | C44: =if(AND(O44>J44,P44>=R44),"SELL Today","Do Not SELL Today") -> Do Not SELL Today | D44: =if(AND(P44<S44,O44>J44,P44<=0.995*T44),"BUY Today","Do Not BUY Today") -> Do Not BUY Today | E44: ='IGL-GAIL'!N2 -> 0.61435071 | F44: ='IGL-GAIL'!N3 -> 0.52428829 | G44: ='IGL-GAIL'!N4 -> -0.049324114 | H44: 30 DAYS | I44: ='IGL-GAIL'!P2 -> 0.85763047 | J44: ='IGL-GAIL'!Q2 -> 0.91141869 | K44: ='IGL-GAIL'!R2 -> 0.82159461 | L44: ='IGL-GAIL'!J128 -> -0.94482543 | M44: =MAX('IGL-GAIL'!J11:J117) -> 2.0773977 | N44: =MIN('IGL-GAIL'!J11:J117) -> -1.5346041 | O44: =P44/P45 -> 0.85086258 | P44: =IFERROR(__xludf.DUMMYFUNCTION("GOOGLEFINANCE(B44,""PRICE"")"),143.03) -> 143.03 | Q44: =IFERROR(__xludf.DUMMYFUNCTION("AVERAGE(QUERY(SORT(GOOGLEFINANCE(B44,""price"",TODAY()-320,TODAY()),1,0),""select Col2 limit 20""))"),144.67749999999998) -> 144.6775 | R44: ='IGL-GAIL'!C3 -> 154.8 | S44: ='IGL-GAIL'!C8 -> 147.62905 | T44: ='IGL-GAIL'!C4 -> 141.38 | U44: ='IGL-GAIL'!P116 -> -0.015179884 | V44: 30 DAYS | W44: =MAX('IGL-GAIL'!P87:P116) -> 0.050413852 | X44: =min('IGL-GAIL'!P87:P116) -> -0.038380652 | Y44: =(P44*A44)/(P45*A45) -> 0.25572373 | Z44: =(A44*P44)-(A45*P45) -> -572391.25 | AA44: =if((AD44="BUY"), -(Z44/P44)) -> 4001.8965 | AB44: =P44*A44 -> 196666.25 | AD44: =if( Z44<0,"Buy","Do Not buy") -> Buy
A45: 4575 | B45: NSE:GAIL | C45: =if(AND(O45>J45,P45>=R45),"SELL Today","Do Not SELL Today") -> Do Not SELL Today | D45: =if(AND(P45<S45,O45>J45,P45<=0.995*T45),"BUY Today","Do Not BUY Today") -> Do Not BUY Today | H45: 60 DAYS | I45: ='IGL-GAIL'!P3 -> 0.86633083 | J45: ='IGL-GAIL'!Q3 -> 0.91141869 | K45: ='IGL-GAIL'!R3 -> 0.82159461 | O45: =P44/P45 -> 0.85086258 | P45: =IFERROR(__xludf.DUMMYFUNCTION("GOOGLEFINANCE(B45,""PRICE"")"),168.1) -> 168.1 | Q45: =IFERROR(__xludf.DUMMYFUNCTION("AVERAGE(QUERY(SORT(GOOGLEFINANCE(B45,""price"",TODAY()-320,TODAY()),1,0),""select Col2 limit 20""))"),170.31799999999998) -> 170.318 | R45: ='IGL-GAIL'!F3 -> 176 | S45: ='IGL-GAIL'!F8 -> 172.38238 | T45: ='IGL-GAIL'!F4 -> 167.5 | V45: 60 days | W45: =MAX('IGL-GAIL'!P57:P116) -> 0.050413852 | X45: =min('IGL-GAIL'!P57:P116) -> -0.052650576 | AA45: =if((AD45="BUY"), (Z44/P45)) -> FALSE | AC45: =P45*A45 -> 769057.5
A47: 100 | B47: NSE:ALKEM | C47: =if(AND(O47>J47,P47>=R47),"SELL Today","Do Not SELL Today") -> Do Not SELL Today | D47: =if(AND(P47<S47,O47>J47,P47<=0.995*T47),"BUY Today","Do Not BUY Today") -> Do Not BUY Today | E47: ='ALKEM-AURO'!N2 -> 0.19933607 | F47: ='ALKEM-AURO'!N3 -> -0.712816 | G47: ='ALKEM-AURO'!N4 -> -0.20368985 | H47: 30 DAYS | I47: ='ALKEM-AURO'!P2 -> 3.143868 | J47: ='ALKEM-AURO'!Q2 -> 3.3271144 | K47: ='ALKEM-AURO'!R2 -> 3.0248985 | L47: ='ALKEM-AURO'!J129 -> -2.3456303 | M47: =MAX('ALKEM-AURO'!J11:J117) -> 1.8828849 | N47: =MIN('ALKEM-AURO'!J11:J117) -> -2.2242658 | O47: =P47/P48 -> 3.0295759 | P47: =IFERROR(__xludf.DUMMYFUNCTION("GOOGLEFINANCE(B47,""PRICE"")"),5050.0) -> 5050 | Q47: =IFERROR(__xludf.DUMMYFUNCTION("AVERAGE(QUERY(SORT(GOOGLEFINANCE(B47,""price"",TODAY()-320,TODAY()),1,0),""select Col2 limit 20""))"),5258.9) -> 5258.9 | R47: ='ALKEM-AURO'!C3 -> 5466.5 | S47: ='ALKEM-AURO'!C8 -> 5252.1667 | T47: ='ALKEM-AURO'!C4 -> 5087.5 | U47: ='ALKEM-AURO'!P116 -> -0.0017106531 | V47: 30 DAYS | W47: =MAX('IGL-GAIL'!P93:P129) -> 0.050413852 | X47: =min('IGL-GAIL'!P93:P129) -> -0.042409566 | Y47: =(P47*A47)/(P48*A48) -> 0.55083197 | Z47: =(A47*P47)-(A48*P48) -> -411795 | AA47: =if((AD47="BUY"), -(Z47/P47)) -> 81.543564 | AB47: =P47*A47 -> 505000 | AD47: =if( Z47<0,"Buy","Do Not buy") -> Buy
A48: 550 | B48: NSE:AUROPHARMA | C48: =if(AND(O48>J48,P48>=R48),"SELL Today","Do Not SELL Today") -> Do Not SELL Today | D48: =if(AND(P48<S48,O48>J48,P48<=0.995*T48),"BUY Today","Do Not BUY Today") -> Do Not BUY Today | H48: 60 DAYS | I48: ='ALKEM-AURO'!P3 -> 3.3292221 | J48: ='ALKEM-AURO'!Q3 -> 3.6899702 | K48: ='ALKEM-AURO'!R3 -> 3.0248985 | L48: ='ALKEM-AURO'!T4 | O48: =P47/P48 -> 3.0295759 | P48: =IFERROR(__xludf.DUMMYFUNCTION("GOOGLEFINANCE(B48,""PRICE"")"),1666.9) -> 1666.9 | Q48: =IFERROR(__xludf.DUMMYFUNCTION("AVERAGE(QUERY(SORT(GOOGLEFINANCE(B48,""price"",TODAY()-320,TODAY()),1,0),""select Col2 limit 20""))"),1691.39) -> 1691.39 | R48: ='ALKEM-AURO'!F3 -> 1734 | S48: ='ALKEM-AURO'!F8 -> 1689.6524 | T48: ='ALKEM-AURO'!F4 -> 1643 | V48: 60 days | W48: =MAX('IGL-GAIL'!P63:P129) -> 0.050413852 | X48: =min('IGL-GAIL'!P63:P129) -> -0.045579347 | AA48: =if((AD48="BUY"), (Z47/P48)) -> FALSE | AC48: =P48*A48 -> 916795
A50: 1320 | B50: NSE:BERGEPAINT | C50: =if(AND(O50>J50,P50>=R50),"SELL Today","Do Not SELL Today") -> Do Not SELL Today | D50: =if(AND(P50<S50,O50>J50,P50<=0.995*T50),"BUY Today","Do Not BUY Today") -> Do Not BUY Today | E50: ='BERGER-ASIAN'!N2 -> 0.91383629 | F50: ='BERGER-ASIAN'!N3 -> 0.88013683 | G50: ='BERGER-ASIAN'!N4 -> 0.83627741 | H50: 30 DAYS | I50: ='BERGER-ASIAN'!P2 -> 0.18936815 | J50: ='BERGER-ASIAN'!Q2 -> 0.19972527 | K50: ='BERGER-ASIAN'!R2 -> 0.18280359 | L50: ='BERGER-ASIAN'!J129 -> 2.9782147 | M50: =MAX('BERGER-ASIAN'!J11:J117) -> 2.3943339 | N50: =MIN('BERGER-ASIAN'!J11:J117) -> -1.8503781 | O50: =P50/P51 -> 0.20412539 | P50: =IFERROR(__xludf.DUMMYFUNCTION("GOOGLEFINANCE(B50,""PRICE"")"),476.0) -> 476 | Q50: =IFERROR(__xludf.DUMMYFUNCTION("AVERAGE(QUERY(SORT(GOOGLEFINANCE(B50,""price"",TODAY()-320,TODAY()),1,0),""select Col2 limit 20""))"),461.9374999999999) -> 461.9375 | R50: ='BERGER-ASIAN'!C3 -> 484.5 | S50: ='BERGER-ASIAN'!C8 -> 458.74048 | T50: ='BERGER-ASIAN'!C4 -> 447.1 | U50: ='BERGER-ASIAN'!P116 -> 0.031506242 | V50: 30 DAYS | W50: =MAX('IGL-GAIL'!P96:P127) -> 0.050413852 | X50: =min('IGL-GAIL'!P96:P127) -> -0.042409566 | Y50: =(P50*A50)/(P51*A51) -> 1.3472276 | Z50: =(A50*P50)-(A51*P51) -> 161940 | AA50: =if((AD50="BUY"), -(Z50/P50)) -> FALSE | AB50: =P50*A50 -> 628320 | AD50: =if( Z50<0,"Buy","Do Not buy") -> Do Not buy
A51: 200 | B51: NSE:ASIANPAINT | C51: =if(AND(O51>J51,P51>=R51),"SELL Today","Do Not SELL Today") -> Do Not SELL Today | D51: =if(AND(P51<S51,O51>J51,P51<=0.995*T51),"BUY Today","Do Not BUY Today") -> Do Not BUY Today | H51: 60 DAYS | I51: ='BERGER-ASIAN'!P3 -> 0.19081273 | J51: ='BERGER-ASIAN'!Q3 -> 0.20590473 | K51: ='BERGER-ASIAN'!R3 -> 0.18232147 | O51: =P50/P51 -> 0.20412539 | P51: =IFERROR(__xludf.DUMMYFUNCTION("GOOGLEFINANCE(B51,""PRICE"")"),2331.9) -> 2331.9 | Q51: =IFERROR(__xludf.DUMMYFUNCTION("AVERAGE(QUERY(SORT(GOOGLEFINANCE(B51,""price"",TODAY()-320,TODAY()),1,0),""select Col2 limit 20""))"),2391.15) -> 2391.15 | R51: ='BERGER-ASIAN'!F3 -> 2500.9 | S51: ='BERGER-ASIAN'!F8 -> 2435.9143 | T51: ='BERGER-ASIAN'!F4 -> 2366 | V51: 60 days | W51: =MAX('IGL-GAIL'!P66:P127) -> 0.050413852 | X51: =min('IGL-GAIL'!P66:P127) -> -0.045579347 | AA51: =if((AD51="BUY"), (Z50/P51)) -> FALSE | AC51: =P51*A51 -> 466380
A53: 1250 | B53: MCX:NAURALGAS1 | C53: =if(AND(O53>J53,P53>=R53),"SELL Today","Do Not SELL Today") -> Do Not SELL Today | D53: =if(AND(P53<S53,O53>J53,P53<=0.995*T53),"BUY Today","Do Not BUY Today") -> Do Not BUY Today | E53: ='Natural Gas -Crude'!M2 -> -0.54013102 | F53: ='Natural Gas -Crude'!M3 -> 0.29795846 | G53: ='Natural Gas -Crude'!M4 -> 0.26282713 | H53: 30 DAYS | I53: ='Natural Gas -Crude'!O2 -> 0.029799831 | J53: ='Natural Gas -Crude'!P2 -> 0.03470201 | K53: ='Natural Gas -Crude'!Q2 -> 0.025190597 | L53: ='Natural Gas -Crude'!J18 -> -0.10481902 | M53: =max('Natural Gas -Crude'!J18:J129) -> 0.11155457 | N53: =min('Natural Gas -Crude'!J18:J129) -> -0.16158744 | O53: ='Natural Gas -Crude'!H18 -> 0.033050127 | P53: ='Natural Gas -Crude'!B18 -> 194.5 | Q53: ='Natural Gas -Crude'!B1 -> 182.98571 | R53: ='Natural Gas -Crude'!B3 -> 200.3 | S53: ='Natural Gas -Crude'!B8 -> 182.98571 | T53: ='Natural Gas -Crude'!B4 -> 158.6 | U53: ='IGL-GAIL'!P119 -> -0.0080369584 | V53: 30 DAYS | W53: =MAX('IGL-GAIL'!P90:P119) -> 0.050413852 | X53: =min('IGL-GAIL'!P90:P119) -> -0.042409566 | Y53: =(P53*A53)/(P54*A54) -> 0.41312659 | Z53: =(A53*P53)-(A54*P54) -> -345375 | AA53: =if((AD53="BUY"), -(Z53/P53)) -> 1775.7069 | AB53: =P53*A53 -> 243125 | AD53: =if( Z53<0,"Buy","Do Not buy") -> Buy
A54: 100 | B54: MCX:CRUDE | C54: =if(AND(O54>J54,P54>=R54),"SELL Today","Do Not SELL Today") -> Do Not SELL Today | D54: =if(AND(P54<S54,O54>J54,P54<=0.995*T54),"BUY Today","Do Not BUY Today") -> Do Not BUY Today | H54: 60 DAYS | I54: ='IGL-GAIL'!P6 | J54: ='IGL-GAIL'!Q6 | K54: ='IGL-GAIL'!R6 | O54: ='Natural Gas -Crude'!H19 -> 0.032860007 | P54: ='Natural Gas -Crude'!E18 -> 5885 | Q54: ='Natural Gas -Crude'!E1 -> 6029.619 | R54: ='Natural Gas -Crude'!E3 -> 6483 | S54: ='Natural Gas -Crude'!E8 -> 6029.619 | T54: ='Natural Gas -Crude'!E4 -> 5537 | V54: 60 days | W54: =MAX('IGL-GAIL'!P60:P119) -> 0.050413852 | X54: =min('IGL-GAIL'!P60:P119) -> -0.052650576 | AA54: =if((AD54="BUY"), (Z53/P54)) -> FALSE | AC54: =P54*A54 -> 588500
A56: 2925 | B56: NSE:BANKBARODA | C56: =if(AND(O56>J56,P56>=R56),"SELL Today","Do Not SELL Today") -> Do Not SELL Today | D56: =if(AND(P56<S56,O56>J56,P56<=0.995*T56),"BUY Today","Do Not BUY Today") -> Do Not BUY Today | E56: ='BOB-CANARA'!N2 -> 0.92320067 | F56: ='BOB-CANARA'!N3 -> 0.80295328 | G56: ='BOB-CANARA'!N4 -> 0.76486162 | H56: 30 DAYS | I56: ='BOB-CANARA'!P2 -> 1.8944958 | J56: ='BOB-CANARA'!Q2 -> 1.9302579 | K56: ='BOB-CANARA'!R2 -> 1.8610008 | L56: ='BOB-CANARA'!J130 -> -1.0485888 | M56: =MAX('BOB-CANARA'!J17:J132) -> 2.1785716 | N56: =MIN('BOB-CANARA'!J17:J132) -> -1.4825066 | O56: =P56/P57 -> 1.9477555 | P56: =IFERROR(__xludf.DUMMYFUNCTION("GOOGLEFINANCE(B56,""PRICE"")"),230.4) -> 230.4 | Q56: =IFERROR(__xludf.DUMMYFUNCTION("AVERAGE(QUERY(SORT(GOOGLEFINANCE(B56,""price"",TODAY()-320,TODAY()),1,0),""select Col2 limit 20""))"),232.85100000000003) -> 232.851 | R56: ='BOB-CANARA'!C3 -> 241.2 | S56: ='BOB-CANARA'!C8 -> 234.76095 | T56: ='BOB-CANARA'!C4 -> 227.5 | U56: ='BOB-CANARA'!P116 -> 0.0046448021 | V56: 30 DAYS | W56: =MAX('IGL-GAIL'!P102:P135) -> 0.026278242 | X56: =min('IGL-GAIL'!P102:P135) -> -0.042409566 | Y56: =(P56*A56)/(P57*A57) -> 0.84402739 | Z56: =(A56*P56)-(A57*P57) -> -124537.5 | AA56: =if((AD56="BUY"), -(Z56/P56)) -> 540.52734 | AB56: =P56*A56 -> 673920 | AD56: =if( Z56<0,"Buy","Do Not buy") -> Buy
A57: 6750 | B57: NSE:CANBK | C57: =if(AND(O57>J57,P57>=R57),"SELL Today","Do Not SELL Today") -> Do Not SELL Today | D57: =if(AND(P57<S57,O57>J57,P57<=0.995*T57),"BUY Today","Do Not BUY Today") -> Do Not BUY Today | H57: 60 DAYS | I57: ='BOB-CANARA'!P3 -> 1.913475 | J57: ='BOB-CANARA'!Q3 -> 1.9847297 | K57: ='BOB-CANARA'!R3 -> 1.8610008 | O57: =P56/P57 -> 1.9477555 | P57: =IFERROR(__xludf.DUMMYFUNCTION("GOOGLEFINANCE(B57,""PRICE"")"),118.29) -> 118.29 | Q57: =IFERROR(__xludf.DUMMYFUNCTION("AVERAGE(QUERY(SORT(GOOGLEFINANCE(B57,""price"",TODAY()-320,TODAY()),1,0),""select Col2 limit 20""))"),120.8315) -> 120.8315 | R57: ='BOB-CANARA'!F3 -> 126.3 | S57: ='BOB-CANARA'!F8 -> 123.50762 | T57: ='BOB-CANARA'!F4 -> 118.36 | V57: 60 days | W57: =MAX('IGL-GAIL'!P72:P135) -> 0.050413852 | X57: =min('IGL-GAIL'!P72:P135) -> -0.045579347 | AA57: =if((AD57="BUY"), (Z56/P57)) -> FALSE | AC57: =P57*A57 -> 798457.5
A59: 2925 | B59: NSE:COALINDIA | C59: =if(AND(O59>J59,P59>=R59),"SELL Today","Do Not SELL Today") -> Do Not SELL Today | D59: =if(AND(P59<S59,O59>J59,P59<=0.995*T59),"BUY Today","Do Not BUY Today") -> Do Not BUY Today | E59: ='COAL-GAIL'!N2 -> 0.012743309 | F59: ='COAL-GAIL'!N3 -> -0.075781314 | G59: ='COAL-GAIL'!N4 -> -0.32217201 | H59: 30 DAYS | I59: ='COAL-GAIL'!P2 -> 2.4106723 | J59: ='COAL-GAIL'!Q2 -> 2.5098507 | K59: ='COAL-GAIL'!R2 -> 2.2633803 | L59: ='COAL-GAIL'!J130 -> -0.53048541 | M59: =mAX('COAL-GAIL'!J17:J132) -> 2.0354067 | N59: =mIN('COAL-GAIL'!J17:J132) -> -1.5114457 | O59: =P59/P60 -> 2.481856 | P59: =IFERROR(__xludf.DUMMYFUNCTION("GOOGLEFINANCE(B59,""PRICE"")"),417.2) -> 417.2 | Q59: =IFERROR(__xludf.DUMMYFUNCTION("AVERAGE(QUERY(SORT(GOOGLEFINANCE(B59,""price"",TODAY()-320,TODAY()),1,0),""select Col2 limit 20""))"),417.7900000000001) -> 417.79 | R59: ='COAL-GAIL'!C3 -> 432 | S59: ='COAL-GAIL'!C8 -> 421.82143 | T59: ='COAL-GAIL'!C4 -> 409.9 | U59: ='COAL-GAIL'!P116 -> 0.0057662063 | V59: 30 DAYS | W59: =MAX('IGL-GAIL'!P105:P138) -> 0.026278242 | X59: =min('IGL-GAIL'!P105:P138) -> -0.042409566 | Y59: =(P59*A59)/(P60*A60) -> 1.0754709 | Z59: =(A59*P59)-(A60*P60) -> 85635 | AA59: =if((AD59="BUY"), -(Z59/P59)) -> FALSE | AB59: =P59*A59 -> 1220310 | AD59: =if( Z59<0,"Buy","Do Not buy") -> Do Not buy
...

Sheet INDICES
A1: =IFERROR(__xludf.DUMMYFUNCTION("GOOGLEFINANCE(B3,""TRADETIME"")"),46311.6466087963) -> 46311.647 | S1: 0.46597222
A2: INDICES | B2: CODE | C2: CURRENT PRICE | D2: CHANGE | E2: CHANGE% | F2: OPEN | G2: HIGH | H2: LOW | O2: =C3*9 -> 208315.35 | Q2: sell | R2: 19684 | S2: 18 | T2: =C3 -> 23146.15 | U2: =R2-T2 -> -3462.15 | V2: =U2*S2*50 -> -3115935
A3: NIFTY 50 | B3: INDEXNSE:NIFTY_50 | C3: =IFERROR(__xludf.DUMMYFUNCTION("GOOGLEFINANCE(B3, ""PRICE"")"),23146.15) -> 23146.15 | D3: =IFERROR(__xludf.DUMMYFUNCTION("GOOGLEFINANCE(B3, ""CHANGE"")"),148.8) -> 148.8 | E3: =IFERROR(__xludf.DUMMYFUNCTION("GOOGLEFINANCE(B3, ""CHANGEPCT"")"),0.65) -> 0.65 | F3: =IFERROR(__xludf.DUMMYFUNCTION("GOOGLEFINANCE(B3, ""PRICEOPEN"")"),23065.1) -> 23065.1 | G3: =IFERROR(__xludf.DUMMYFUNCTION("GOOGLEFINANCE(B3, ""HIGH"")"),23149.85) -> 23149.85 | H3: =IFERROR(__xludf.DUMMYFUNCTION("GOOGLEFINANCE(B3, ""LOW"")"),22913.8) -> 22913.8 | O3: =C4*4 -> 223376 | Q3: buy | R3: 44698 | S3: 8 | T3: =C4 -> 55844 | U3: =T3-R3 -> 11146 | V3: =U3*S3*15 -> 1337520
A4: BANKNIFTY | B4: INDEXNSE:NIFTY_BANK | C4: =IFERROR(__xludf.DUMMYFUNCTION("GOOGLEFINANCE(B4, ""PRICE"")"),55844.0) -> 55844 | D4: =IFERROR(__xludf.DUMMYFUNCTION("GOOGLEFINANCE(B4, ""CHANGE"")"),33.5) -> 33.5 | E4: =IFERROR(__xludf.DUMMYFUNCTION("GOOGLEFINANCE(B4, ""CHANGEPCT"")"),0.06) -> 0.06 | F4: =IFERROR(__xludf.DUMMYFUNCTION("GOOGLEFINANCE(B4, ""PRICEOPEN"")"),55927.15) -> 55927.15 | G4: =IFERROR(__xludf.DUMMYFUNCTION("GOOGLEFINANCE(B4, ""HIGH"")"),55989.55) -> 55989.55 | H4: =IFERROR(__xludf.DUMMYFUNCTION("GOOGLEFINANCE(B4, ""LOW"")"),55526.3) -> 55526.3 | V4: =V2+V3 -> -1778415
A5: RELIANCE | B5: NSE:RELIANCE | C5: =IFERROR(__xludf.DUMMYFUNCTION("GOOGLEFINANCE(B5, ""PRICE"")"),1211.2) -> 1211.2 | D5: =IFERROR(__xludf.DUMMYFUNCTION("GOOGLEFINANCE(B5, ""CHANGE"")"),-3.8) -> -3.8 | E5: =IFERROR(__xludf.DUMMYFUNCTION("GOOGLEFINANCE(B5, ""CHANGEPCT"")"),-0.31) -> -0.31 | F5: =IFERROR(__xludf.DUMMYFUNCTION("GOOGLEFINANCE(B5, ""PRICEOPEN"")"),1215.0) -> 1215 | G5: =IFERROR(__xludf.DUMMYFUNCTION("GOOGLEFINANCE(B5, ""HIGH"")"),1215.4) -> 1215.4 | H5: =IFERROR(__xludf.DUMMYFUNCTION("GOOGLEFINANCE(B5, ""LOW"")"),1193.0) -> 1193
A6: HDFCBANK | B6: NSE:HDFCBANK | C6: =IFERROR(__xludf.DUMMYFUNCTION("GOOGLEFINANCE(B6, ""PRICE"")"),728.85) -> 728.85 | D6: =IFERROR(__xludf.DUMMYFUNCTION("GOOGLEFINANCE(B6, ""CHANGE"")"),2.0) -> 2 | E6: =IFERROR(__xludf.DUMMYFUNCTION("GOOGLEFINANCE(B6, ""CHANGEPCT"")"),0.28) -> 0.28 | F6: =IFERROR(__xludf.DUMMYFUNCTION("GOOGLEFINANCE(B6, ""PRICEOPEN"")"),727.9) -> 727.9 | G6: =IFERROR(__xludf.DUMMYFUNCTION("GOOGLEFINANCE(B6, ""HIGH"")"),734.9) -> 734.9 | H6: =IFERROR(__xludf.DUMMYFUNCTION("GOOGLEFINANCE(B6, ""LOW"")"),724.3) -> 724.3 | L6: NIFTY
K7: CURRENT | L7: =C3 -> 23146.15
A8: NIFTY | B8: =IFERROR(__xludf.DUMMYFUNCTION("GOOGLEFINANCE(""INDEXNSE:NIFTY_50"",""price"",TODAY()-120,TODAY())"),"Date") -> Date | C8: =IFERROR(__xludf.DUMMYFUNCTION("""COMPUTED_VALUE"""),"Close") -> Close | J8: -2SD | K8: -1SD | L8: MEAN | M8: 1SD | N8: 2SD | P8: SBIN | Q8: =IFERROR(__xludf.DUMMYFUNCTION("GOOGLEFINANCE(""NSE:SBIN"",""price"",TODAY()-121,TODAY())"),"Date") -> Date | R8: =IFERROR(__xludf.DUMMYFUNCTION("""COMPUTED_VALUE"""),"Close") -> Close
B9: =IFERROR(__xludf.DUMMYFUNCTION("""COMPUTED_VALUE"""),46192.64583333333) -> 46192.646 | C9: =IFERROR(__xludf.DUMMYFUNCTION("""COMPUTED_VALUE"""),24013.1) -> 24013.1 | F9: SMA 20 | G9: =AVERAGE(C72:C91) -> 22840.88 | H9: SD | I9: =STDEV(C72:C91) -> 369.594 | J9: =L9-2*I9 -> 22101.692 | K9: =L9-I9 -> 22471.286 | L9: =G9 -> 22840.88 | M9: =L9+I9 -> 23210.474 | N9: =L9+I9*2 -> 23580.068 | Q9: =IFERROR(__xludf.DUMMYFUNCTION("""COMPUTED_VALUE"""),46191.64583333333) -> 46191.646 | R9: =IFERROR(__xludf.DUMMYFUNCTION("""COMPUTED_VALUE"""),1042.7) -> 1042.7 | T9: Neutrality | U9: =C3*S2 -> 416630.7 | V9: =U9/U10 -> 0.93257713
B10: =IFERROR(__xludf.DUMMYFUNCTION("""COMPUTED_VALUE"""),46195.64583333333) -> 46195.646 | C10: =IFERROR(__xludf.DUMMYFUNCTION("""COMPUTED_VALUE"""),24102.9) -> 24102.9 | D10: =if(C10>C9,"UP","DOWN") -> UP | F10: SMA 10 | G10: =AVERAGE(C82:C91) -> 22653.865 | H10: SD | I10: =STDEV(C82:C91) -> 273.54073 | Q10: =IFERROR(__xludf.DUMMYFUNCTION("""COMPUTED_VALUE"""),46192.64583333333) -> 46192.646 | R10: =IFERROR(__xludf.DUMMYFUNCTION("""COMPUTED_VALUE"""),1035.1) -> 1035.1 | S10: =if(R10>R9,"UP","DOWN") -> DOWN | U10: =C4*S3 -> 446752
B11: =IFERROR(__xludf.DUMMYFUNCTION("""COMPUTED_VALUE"""),46196.64583333333) -> 46196.646 | C11: =IFERROR(__xludf.DUMMYFUNCTION("""COMPUTED_VALUE"""),23824.1) -> 23824.1 | D11: =if(C11>C10,"UP","DOWN") -> DOWN | Q11: =IFERROR(__xludf.DUMMYFUNCTION("""COMPUTED_VALUE"""),46195.64583333333) -> 46195.646 | R11: =IFERROR(__xludf.DUMMYFUNCTION("""COMPUTED_VALUE"""),1040.75) -> 1040.75 | S11: =if(R11>R10,"UP","DOWN") -> UP
B12: =IFERROR(__xludf.DUMMYFUNCTION("""COMPUTED_VALUE"""),46197.64583333333) -> 46197.646 | C12: =IFERROR(__xludf.DUMMYFUNCTION("""COMPUTED_VALUE"""),24021.65) -> 24021.65 | D12: =if(C12>C11,"UP","DOWN") -> UP | L12: BANK NIFTY | Q12: =IFERROR(__xludf.DUMMYFUNCTION("""COMPUTED_VALUE"""),46196.64583333333) -> 46196.646 | R12: =IFERROR(__xludf.DUMMYFUNCTION("""COMPUTED_VALUE"""),1024.2) -> 1024.2 | S12: =if(R12>R11,"UP","DOWN") -> DOWN
B13: =IFERROR(__xludf.DUMMYFUNCTION("""COMPUTED_VALUE"""),46198.64583333333) -> 46198.646 | C13: =IFERROR(__xludf.DUMMYFUNCTION("""COMPUTED_VALUE"""),24056.0) -> 24056 | D13: =if(C13>C12,"UP","DOWN") -> UP | K13: CURRENT | L13: =C4 -> 55844 | Q13: =IFERROR(__xludf.DUMMYFUNCTION("""COMPUTED_VALUE"""),46197.64583333333) -> 46197.646 | R13: =IFERROR(__xludf.DUMMYFUNCTION("""COMPUTED_VALUE"""),1034.6) -> 1034.6 | S13: =if(R13>R12,"UP","DOWN") -> UP
B14: =IFERROR(__xludf.DUMMYFUNCTION("""COMPUTED_VALUE"""),46202.64583333333) -> 46202.646 | C14: =IFERROR(__xludf.DUMMYFUNCTION("""COMPUTED_VALUE"""),23946.25) -> 23946.25 | D14: =if(C14>C13,"UP","DOWN") -> DOWN | J14: -2SD | K14: -1SD | L14: MEAN | M14: 1SD | N14: 2SD | Q14: =IFERROR(__xludf.DUMMYFUNCTION("""COMPUTED_VALUE"""),46198.64583333333) -> 46198.646 | R14: =IFERROR(__xludf.DUMMYFUNCTION("""COMPUTED_VALUE"""),1045.4) -> 1045.4 | S14: =if(R14>R13,"UP","DOWN") -> UP
B15: =IFERROR(__xludf.DUMMYFUNCTION("""COMPUTED_VALUE"""),46203.64583333333) -> 46203.646 | C15: =IFERROR(__xludf.DUMMYFUNCTION("""COMPUTED_VALUE"""),23865.75) -> 23865.75 | D15: =if(C15>C14,"UP","DOWN") -> DOWN | F15: SMA 20 | G15: =AVERAGE(C158:C177) -> 55333.957 | H15: SD | I15: =STDEV(C158:C177) -> 723.99274 | J15: =L15-2*I15 -> 53885.972 | K15: =L15-I15 -> 54609.965 | L15: =G15 -> 55333.957 | M15: =L15+I15 -> 56057.95 | N15: =L15+I15*2 -> 56781.943 | Q15: =IFERROR(__xludf.DUMMYFUNCTION("""COMPUTED_VALUE"""),46202.64583333333) -> 46202.646 | R15: =IFERROR(__xludf.DUMMYFUNCTION("""COMPUTED_VALUE"""),1036.1) -> 1036.1 | S15: =if(R15>R14,"UP","DOWN") -> DOWN
B16: =IFERROR(__xludf.DUMMYFUNCTION("""COMPUTED_VALUE"""),46204.64583333333) -> 46204.646 | C16: =IFERROR(__xludf.DUMMYFUNCTION("""COMPUTED_VALUE"""),24005.85) -> 24005.85 | D16: =if(C16>C15,"UP","DOWN") -> UP | F16: SMA 10 | G16: =AVERAGE(C168:C177) -> 55064.605 | H16: SD | I16: =STDEV(C168:C177) -> 429.10679 | Q16: =IFERROR(__xludf.DUMMYFUNCTION("""COMPUTED_VALUE"""),46203.64583333333) -> 46203.646 | R16: =IFERROR(__xludf.DUMMYFUNCTION("""COMPUTED_VALUE"""),1026.9) -> 1026.9 | S16: =if(R16>R15,"UP","DOWN") -> DOWN
B17: =IFERROR(__xludf.DUMMYFUNCTION("""COMPUTED_VALUE"""),46205.64583333333) -> 46205.646 | C17: =IFERROR(__xludf.DUMMYFUNCTION("""COMPUTED_VALUE"""),24175.7) -> 24175.7 | D17: =if(C17>C16,"UP","DOWN") -> UP | Q17: =IFERROR(__xludf.DUMMYFUNCTION("""COMPUTED_VALUE"""),46204.64583333333) -> 46204.646 | R17: =IFERROR(__xludf.DUMMYFUNCTION("""COMPUTED_VALUE"""),1047.4) -> 1047.4 | S17: =if(R17>R16,"UP","DOWN") -> UP
B18: =IFERROR(__xludf.DUMMYFUNCTION("""COMPUTED_VALUE"""),46206.64583333333) -> 46206.646 | C18: =IFERROR(__xludf.DUMMYFUNCTION("""COMPUTED_VALUE"""),24270.85) -> 24270.85 | D18: =if(C18>C17,"UP","DOWN") -> UP | Q18: =IFERROR(__xludf.DUMMYFUNCTION("""COMPUTED_VALUE"""),46205.64583333333) -> 46205.646 | R18: =IFERROR(__xludf.DUMMYFUNCTION("""COMPUTED_VALUE"""),1051.6) -> 1051.6 | S18: =if(R18>R17,"UP","DOWN") -> UP
B19: =IFERROR(__xludf.DUMMYFUNCTION("""COMPUTED_VALUE"""),46209.64583333333) -> 46209.646 | C19: =IFERROR(__xludf.DUMMYFUNCTION("""COMPUTED_VALUE"""),24430.35) -> 24430.35 | D19: =if(C19>C18,"UP","DOWN") -> UP | L19: SBIN | Q19: =IFERROR(__xludf.DUMMYFUNCTION("""COMPUTED_VALUE"""),46206.64583333333) -> 46206.646 | R19: =IFERROR(__xludf.DUMMYFUNCTION("""COMPUTED_VALUE"""),1040.0) -> 1040 | S19: =if(R19>R18,"UP","DOWN") -> DOWN
B20: =IFERROR(__xludf.DUMMYFUNCTION("""COMPUTED_VALUE"""),46210.64583333333) -> 46210.646 | C20: =IFERROR(__xludf.DUMMYFUNCTION("""COMPUTED_VALUE"""),24398.7) -> 24398.7 | D20: =if(C20>C19,"UP","DOWN") -> DOWN | K20: CURRENT | L20: =C5 -> 1211.2 | Q20: =IFERROR(__xludf.DUMMYFUNCTION("""COMPUTED_VALUE"""),46209.64583333333) -> 46209.646 | R20: =IFERROR(__xludf.DUMMYFUNCTION("""COMPUTED_VALUE"""),1037.7) -> 1037.7 | S20: =if(R20>R19,"UP","DOWN") -> DOWN
B21: =IFERROR(__xludf.DUMMYFUNCTION("""COMPUTED_VALUE"""),46211.64583333333) -> 46211.646 | C21: =IFERROR(__xludf.DUMMYFUNCTION("""COMPUTED_VALUE"""),23882.05) -> 23882.05 | D21: =if(C21>C20,"UP","DOWN") -> DOWN | J21: -2SD | K21: -1SD | L21: MEAN | M21: 1SD | N21: 2SD | Q21: =IFERROR(__xludf.DUMMYFUNCTION("""COMPUTED_VALUE"""),46210.64583333333) -> 46210.646 | R21: =IFERROR(__xludf.DUMMYFUNCTION("""COMPUTED_VALUE"""),1038.1) -> 1038.1 | S21: =if(R21>R20,"UP","DOWN") -> UP
B22: =IFERROR(__xludf.DUMMYFUNCTION("""COMPUTED_VALUE"""),46212.64583333333) -> 46212.646 | C22: =IFERROR(__xludf.DUMMYFUNCTION("""COMPUTED_VALUE"""),23962.8) -> 23962.8 | D22: =if(C22>C21,"UP","DOWN") -> UP | F22: SMA 20 | G22: =AVERAGE(R72:R91) -> 967.3275 | H22: SD | I22: =STDEV(R72:R91) -> 17.798399 | J22: =L22-2*I22 -> 931.7307 | K22: =L22-I22 -> 949.5291 | L22: =G22 -> 967.3275 | M22: =L22+I22 -> 985.1259 | N22: =L22+I22*2 -> 1002.9243 | Q22: =IFERROR(__xludf.DUMMYFUNCTION("""COMPUTED_VALUE"""),46211.64583333333) -> 46211.646 | R22: =IFERROR(__xludf.DUMMYFUNCTION("""COMPUTED_VALUE"""),1016.9) -> 1016.9 | S22: =if(R22>R21,"UP","DOWN") -> DOWN
B23: =IFERROR(__xludf.DUMMYFUNCTION("""COMPUTED_VALUE"""),46213.64583333333) -> 46213.646 | C23: =IFERROR(__xludf.DUMMYFUNCTION("""COMPUTED_VALUE"""),24206.9) -> 24206.9 | D23: =if(C23>C22,"UP","DOWN") -> UP | F23: SMA 10 | G23: =AVERAGE(R82:R91) -> 953.685 | H23: SD | I23: =STDEV(R82:R91) -> 7.2602437 | Q23: =IFERROR(__xludf.DUMMYFUNCTION("""COMPUTED_VALUE"""),46212.64583333333) -> 46212.646 | R23: =IFERROR(__xludf.DUMMYFUNCTION("""COMPUTED_VALUE"""),1022.1) -> 1022.1 | S23: =if(R23>R22,"UP","DOWN") -> UP
B24: =IFERROR(__xludf.DUMMYFUNCTION("""COMPUTED_VALUE"""),46216.64583333333) -> 46216.646 | C24: =IFERROR(__xludf.DUMMYFUNCTION("""COMPUTED_VALUE"""),24211.0) -> 24211 | D24: =if(C24>C23,"UP","DOWN") -> UP | Q24: =IFERROR(__xludf.DUMMYFUNCTION("""COMPUTED_VALUE"""),46213.64583333333) -> 46213.646 | R24: =IFERROR(__xludf.DUMMYFUNCTION("""COMPUTED_VALUE"""),1036.0) -> 1036 | S24: =if(R24>R23,"UP","DOWN") -> UP
B25: =IFERROR(__xludf.DUMMYFUNCTION("""COMPUTED_VALUE"""),46217.64583333333) -> 46217.646 | C25: =IFERROR(__xludf.DUMMYFUNCTION("""COMPUTED_VALUE"""),24052.05) -> 24052.05 | D25: =if(C25>C24,"UP","DOWN") -> DOWN | Q25: =IFERROR(__xludf.DUMMYFUNCTION("""COMPUTED_VALUE"""),46216.64583333333) -> 46216.646 | R25: =IFERROR(__xludf.DUMMYFUNCTION("""COMPUTED_VALUE"""),1037.0) -> 1037 | S25: =if(R25>R24,"UP","DOWN") -> UP
B26: =IFERROR(__xludf.DUMMYFUNCTION("""COMPUTED_VALUE"""),46218.64583333333) -> 46218.646 | C26: =IFERROR(__xludf.DUMMYFUNCTION("""COMPUTED_VALUE"""),24078.5) -> 24078.5 | D26: =if(C26>C25,"UP","DOWN") -> UP | Q26: =IFERROR(__xludf.DUMMYFUNCTION("""COMPUTED_VALUE"""),46217.64583333333) -> 46217.646 | R26: =IFERROR(__xludf.DUMMYFUNCTION("""COMPUTED_VALUE"""),1015.4) -> 1015.4 | S26: =if(R26>R25,"UP","DOWN") -> DOWN
B27: =IFERROR(__xludf.DUMMYFUNCTION("""COMPUTED_VALUE"""),46219.64583333333) -> 46219.646 | C27: =IFERROR(__xludf.DUMMYFUNCTION("""COMPUTED_VALUE"""),24072.75) -> 24072.75 | D27: =if(C27>C26,"UP","DOWN") -> DOWN | Q27: =IFERROR(__xludf.DUMMYFUNCTION("""COMPUTED_VALUE"""),46218.64583333333) -> 46218.646 | R27: =IFERROR(__xludf.DUMMYFUNCTION("""COMPUTED_VALUE"""),1030.1) -> 1030.1 | S27: =if(R27>R26,"UP","DOWN") -> UP
B28: =IFERROR(__xludf.DUMMYFUNCTION("""COMPUTED_VALUE"""),46220.64583333333) -> 46220.646 | C28: =IFERROR(__xludf.DUMMYFUNCTION("""COMPUTED_VALUE"""),24334.3) -> 24334.3 | D28: =if(C28>C27,"UP","DOWN") -> UP | Q28: =IFERROR(__xludf.DUMMYFUNCTION("""COMPUTED_VALUE"""),46219.64583333333) -> 46219.646 | R28: =IFERROR(__xludf.DUMMYFUNCTION("""COMPUTED_VALUE"""),1031.2) -> 1031.2 | S28: =if(R28>R27,"UP","DOWN") -> UP
B29: =IFERROR(__xludf.DUMMYFUNCTION("""COMPUTED_VALUE"""),46223.64583333333) -> 46223.646 | C29: =IFERROR(__xludf.DUMMYFUNCTION("""COMPUTED_VALUE"""),24238.5) -> 24238.5 | D29: =if(C29>C28,"UP","DOWN") -> DOWN | Q29: =IFERROR(__xludf.DUMMYFUNCTION("""COMPUTED_VALUE"""),46220.64583333333) -> 46220.646 | R29: =IFERROR(__xludf.DUMMYFUNCTION("""COMPUTED_VALUE"""),1044.3) -> 1044.3 | S29: =if(R29>R28,"UP","DOWN") -> UP
B30: =IFERROR(__xludf.DUMMYFUNCTION("""COMPUTED_VALUE"""),46224.64583333333) -> 46224.646 | C30: =IFERROR(__xludf.DUMMYFUNCTION("""COMPUTED_VALUE"""),24187.7) -> 24187.7 | D30: =if(C30>C29,"UP","DOWN") -> DOWN | Q30: =IFERROR(__xludf.DUMMYFUNCTION("""COMPUTED_VALUE"""),46223.64583333333) -> 46223.646 | R30: =IFERROR(__xludf.DUMMYFUNCTION("""COMPUTED_VALUE"""),1060.0) -> 1060 | S30: =if(R30>R29,"UP","DOWN") -> UP
B31: =IFERROR(__xludf.DUMMYFUNCTION("""COMPUTED_VALUE"""),46225.64583333333) -> 46225.646 | C31: =IFERROR(__xludf.DUMMYFUNCTION("""COMPUTED_VALUE"""),23996.25) -> 23996.25 | D31: =if(C31>C30,"UP","DOWN") -> DOWN | Q31: =IFERROR(__xludf.DUMMYFUNCTION("""COMPUTED_VALUE"""),46224.64583333333) -> 46224.646 | R31: =IFERROR(__xludf.DUMMYFUNCTION("""COMPUTED_VALUE"""),1044.4) -> 1044.4 | S31: =if(R31>R30,"UP","DOWN") -> DOWN
B32: =IFERROR(__xludf.DUMMYFUNCTION("""COMPUTED_VALUE"""),46226.64583333333) -> 46226.646 | C32: =IFERROR(__xludf.DUMMYFUNCTION("""COMPUTED_VALUE"""),23869.6) -> 23869.6 | D32: =if(C32>C31,"UP","DOWN") -> DOWN | Q32: =IFERROR(__xludf.DUMMYFUNCTION("""COMPUTED_VALUE"""),46225.64583333333) -> 46225.646 | R32: =IFERROR(__xludf.DUMMYFUNCTION("""COMPUTED_VALUE"""),1025.0) -> 1025 | S32: =if(R32>R31,"UP","DOWN") -> DOWN
B33: =IFERROR(__xludf.DUMMYFUNCTION("""COMPUTED_VALUE"""),46227.64583333333) -> 46227.646 | C33: =IFERROR(__xludf.DUMMYFUNCTION("""COMPUTED_VALUE"""),23767.45) -> 23767.45 | D33: =if(C33>C32,"UP","DOWN") -> DOWN | Q33: =IFERROR(__xludf.DUMMYFUNCTION("""COMPUTED_VALUE"""),46226.64583333333) -> 46226.646 | R33: =IFERROR(__xludf.DUMMYFUNCTION("""COMPUTED_VALUE"""),1012.6) -> 1012.6 | S33: =if(R33>R32,"UP","DOWN") -> DOWN
B34: =IFERROR(__xludf.DUMMYFUNCTION("""COMPUTED_VALUE"""),46230.64583333333) -> 46230.646 | C34: =IFERROR(__xludf.DUMMYFUNCTION("""COMPUTED_VALUE"""),23995.95) -> 23995.95 | D34: =if(C34>C33,"UP","DOWN") -> UP | Q34: =IFERROR(__xludf.DUMMYFUNCTION("""COMPUTED_VALUE"""),46227.64583333333) -> 46227.646 | R34: =IFERROR(__xludf.DUMMYFUNCTION("""COMPUTED_VALUE"""),1015.0) -> 1015 | S34: =if(R34>R33,"UP","DOWN") -> UP
B35: =IFERROR(__xludf.DUMMYFUNCTION("""COMPUTED_VALUE"""),46231.64583333333) -> 46231.646 | C35: =IFERROR(__xludf.DUMMYFUNCTION("""COMPUTED_VALUE"""),23985.35) -> 23985.35 | D35: =if(C35>C34,"UP","DOWN") -> DOWN | Q35: =IFERROR(__xludf.DUMMYFUNCTION("""COMPUTED_VALUE"""),46230.64583333333) -> 46230.646 | R35: =IFERROR(__xludf.DUMMYFUNCTION("""COMPUTED_VALUE"""),1020.6) -> 1020.6 | S35: =if(R35>R34,"UP","DOWN") -> UP
